Workbook

Sheet README
A1: Burkhart Dental Supply – AR Tax Removal Analysis
A3: Date prepared: June 19, 2026
A4: Source file: 2026_06_19_AR_Aging.xlsx (sheet AROpenStatusReportResults)
A5: Data refreshed from NetSuite at time of preparation.
A7: PURPOSE
A8: Cross-reference the AR aging items flagged by Accounting for sales-tax
A9: removal against current NetSuite invoice/tax/payment data, classify by
A10: tier of treatment, and check accounting-period status to determine which
A11: can be edited directly versus which require period unlock or alternate method.
A13: SHEET INDEX
A14: 1. README – this sheet
A15: 2. Executive Summary – tier counts/amounts, period status, recommendations (formula-driven)
... A35: Period Status column uses VLOOKUP against the Period Status sheet.

Sheet Executive Summary
A1: Burkhart Dental Supply – AR Tax Removal Analysis (Executive Summary)
A2: Prepared June 19, 2026 from 2026_06_19_AR_Aging.xlsx + live NetSuite data
A4: CUSTOMERS IN SCOPE
A5: Customer Entity ID | B5: Customer Name | C5: NetSuite Internal ID | D5: Currently Taxable in NS | E5: Notes
A6: 314 | B6: Burkhart Dental Supply Company (parent) | C6: 921 | D6: No (taxable=F) | E6: Parent record; majority of invoices already have no tax line.
A7: 1727 | B7: Heath Hollis (child of Burkhart 314) | C7: 2314 | D7: Yes (taxable=T) | E7: Needs taxable flag updated + exemption certificate attached before edits.
A9: TIER BREAKDOWN (formula-driven from Detail sheet)
A10: Tier | B10: Count | C10: Sum Original Amount | D10: Sum Amount Remaining | E10: Sum Sales Tax | F10: Tax Removal Status | G10: Notes
A11: T1_Clean | B11: =COUNTIF(Detail!O:O,"T1_Clean") | C11: =SUMIF(Detail!O:O,"T1_Clean",Detail!J:J) | D11: =SUMIF(Detail!O:O,"T1_Clean",Detail!K:K) | E11: =SUMIF(Detail!O:O,"T1_Clean",Detail!M:M) | F11: Applicable — direct | G11: Removing tax zeroes the balance. 55 invoices total. Most blocked by period lock (see below).
A12: T2_FullUnpaid | B12: =COUNTIF(Detail!O:O,"T2_FullUnpaid") | C12: =SUMIF(Detail!O:O,"T2_FullUnpaid",Detail!J:J) | D12: =SUMIF(Detail!O:O,"T2_FullUnpaid",Detail!K:K) | E12: =SUMIF(Detail!O:O,"T2_FullUnpaid",Detail!M:M) | F12: Pending decision | G12: Tax present but no payment yet. Accounting must decide remove-now-vs-wait.
A13: T3_Mismatch | B13: =COUNTIF(Detail!O:O,"T3_Mismatch") | C13: =SUMIF(Detail!O:O,"T3_Mismatch",Detail!J:J) | D13: =SUMIF(Detail!O:O,"T3_Mismatch",Detail!K:K) | E13: =SUMIF(Detail!O:O,"T3_Mismatch",Detail!M:M) | F13: Investigate | G13: Unpaid ≠ tax with payments made. Manual NS review per invoice.
A14: T0_NoTax | B14: =COUNTIF(Detail!O:O,"T0_NoTax") | C14: =SUMIF(Detail!O:O,"T0_NoTax",Detail!J:J) | D14: =SUMIF(Detail!O:O,"T0_NoTax",Detail!K:K) | E14: =SUMIF(Detail!O:O,"T0_NoTax",Detail!M:M) | F14: Not applicable | G14: No tax to remove — flag back as different issue.
A15: CM_Pending | B15: =COUNTIF(Detail!O:O,"CM_Pending") | C15: =SUMIF(Detail!O:O,"CM_Pending",Detail!J:J) | D15: =SUMIF(Detail!O:O,"CM_Pending",Detail!K:K) | E15: =SUMIF(Detail!O:O,"CM_Pending",Detail!M:M) | F15: N/A (credit memo) | G15: Apply per accounting team instruction.
A16: CM_Recent | B16: =COUNTIF(Detail!O:O,"CM_Recent") | C16: =SUMIF(Detail!O:O,"CM_Recent",Detail!J:J) | D16: =SUMIF(Detail!O:O,"CM_Recent",Detail!K:K) | E16: =SUMIF(Detail!O:O,"CM_Recent",Detail!M:M) | F16: N/A (credit memo) | G16: Informational only.
A17: TOTAL | B17: =SUM(B11:B16) | C17: =SUM(C11:C16) | D17: =SUM(D11:D16) | E17: =SUM(E11:E16)
A19: TIER × PERIOD FEASIBILITY (counts and sales-tax sums)
A20: Period Feasibility | B20: T1_Clean Count | C20: T1_Clean Tax $ | D20: T2_FullUnpaid Count | E20: T2 Tax $ | F20: T3_Mismatch Count | G20: T0_NoTax Count
A21: OK | B21: =COUNTIFS(Detail!O:O,"T1_Clean",Detail!P:P,"OK") | C21: =SUMIFS(Detail!M:M,Detail!O:O,"T1_Clean",Detail!P:P,"OK") | D21: =COUNTIFS(Detail!O:O,"T2_FullUnpaid",Detail!P:P,"OK") | E21: =SUMIFS(Detail!M:M,Detail!O:O,"T2_FullUnpaid",Detail!P:P,"OK") | F21: =COUNTIFS(Detail!O:O,"T3_Mismatch",Detail!P:P,"OK") | G21: =COUNTIFS(Detail!O:O,"T0_NoTax",Detail!P:P,"OK")
A22: AR LOCKED | B22: =COUNTIFS(Detail!O:O,"T1_Clean",Detail!P:P,"AR LOCKED") | C22: =SUMIFS(Detail!M:M,Detail!O:O,"T1_Clean",Detail!P:P,"AR LOCKED") | D22: =COUNTIFS(Detail!O:O,"T2_FullUnpaid",Detail!P:P,"AR LOCKED") | E22: =SUMIFS(Detail!M:M,Detail!O:O,"T2_FullUnpaid",Detail!P:P,"AR LOCKED") | F22: =COUNTIFS(Detail!O:O,"T3_Mismatch",Detail!P:P,"AR LOCKED") | G22: =COUNTIFS(Detail!O:O,"T0_NoTax",Detail!P:P,"AR LOCKED")
A23: CLOSED+LOCKED | B23: =COUNTIFS(Detail!O:O,"T1_Clean",Detail!P:P,"CLOSED+LOCKED") | C23: =SUMIFS(Detail!M:M,Detail!O:O,"T1_Clean",Detail!P:P,"CLOSED+LOCKED") | D23: =COUNTIFS(Detail!O:O,"T2_FullUnpaid",Detail!P:P,"CLOSED+LOCKED") | E23: =SUMIFS(Detail!M:M,Detail!O:O,"T2_FullUnpaid",Detail!P:P,"CLOSED+LOCKED") | F23: =COUNTIFS(Detail!O:O,"T3_Mismatch",Detail!P:P,"CLOSED+LOCKED") | G23: =COUNTIFS(Detail!O:O,"T0_NoTax",Detail!P:P,"CLOSED+LOCKED")
A24: TOTAL | B24: =SUM(B21:B23) | C24: =SUM(C21:C23) | D24: =SUM(D21:D23) | E24: =SUM(E21:E23) | F24: =SUM(F21:F23) | G24: =SUM(G21:G23)
A26: KEY BLOCKERS
A27: 1. All 55 T1 Clean invoices fall in CLOSED+LOCKED or AR-LOCKED periods (Aug 2025 – Apr 2026).
A28: Direct edit not possible until controller reopens periods + unlocks AR, OR an alternate posting period is used.
A29: 2. Customer 1727 (Heath Hollis) is still flagged taxable=T in NetSuite. Must be updated to taxable=F
A30: with exemption certificate attached BEFORE any edits, otherwise AVATAX will recalc tax on save.
A31: 3. AVATAX (Avalara) integration recalculates tax on invoice save. Per-line taxcode change required
A32: OR AVATAX skip flag must be set per transaction.
A33: 4. Sales tax filings for the relevant periods confirmed NOT YET FILED (per accounting) — compliance OK.
A34: 5. Two partial-pay invoices (INV681804, INV687698) show payment-application oddities that need
A35: manual NetSuite UI review before any tax change.
A36: 6. 26 invoices on the list have NO tax line in NetSuite (already non-taxable). Tax removal does not apply;
A37: these likely represent collection follow-ups, not tax issues.
... A56: Step 7. AR aging re-run; reconcile to expected results.

Sheet Detail
A1: NS Internal ID | B1: Doc Number | C1: Type | D1: Customer EntityID | E1: Customer Name | F1: Tran Date | G1: Due Date | H1: Accounting Period (formula) | I1: Period Feasibility (formula) | J1: Original Amount | K1: Amount Remaining | L1: Amount Paid (formula) | M1: Sales Tax on Invoice | N1: Unpaid - Tax (formula) | O1: Tier (formula) | P1: Edit Feasibility (formula) | Q1: Recommended Action (formula) | R1: Source Note (from accounting team)
A2: 5553 | B2: 61916-CM | C2: CustCred | D2: 314 | E2: Burkhart Dental Supply Company | F2: 45748 | H2: =IFERROR(INDEX('Period Status'!$A$2:$A$16,MATCH(1,(F2>='Period Status'!$C$2:$C$16)*(F2<='Period Status'!$D$2:$D$16),0)),"?") | I2: =IFERROR(VLOOKUP(H2,'Period Status'!$A$2:$I$16,9,FALSE),"?") | J2: -15 | K2: -15 | L2: N/A (CM) | M2: 0 | N2: N/A (CM) | O2: =IF(ISNUMBER(SEARCH("Recently issued",R2)),"CM_Recent","CM_Pending") | P2: =I2 | Q2: =IF(LEFT(O2,2)="CM","See Tier Definitions for CM handling",IF(O2="T1_Clean",IF(P2="OK","Edit invoice to remove tax (immediate)","Edit blocked — requires period unlock by accounting"),IF(O2="T2_FullUnpaid","Hold for accounting decision: remove now or wait for payment",IF(O2="T3_Mismatch","Manual investigation of payment trail in NetSuite required",IF(O2="T0_NoTax","Tax not on invoice — flag back to accounting (collection or other issue)",""))))) | R2: Please let us know what invoice you would like this applied to
A3: 78923 | B3: INV667672 | C3: CustInvc | D3: 314 | E3: Burkhart Dental Supply Company | F3: 45817 | G3: 45847 | H3: =IFERROR(INDEX('Period Status'!$A$2:$A$16,MATCH(1,(F3>='Period Status'!$C$2:$C$16)*(F3<='Period Status'!$D$2:$D$16),0)),"?") | I3: =IFERROR(VLOOKUP(H3,'Period Status'!$A$2:$I$16,9,FALSE),"?") | J3: 257.78 | K3: 96.75 | L3: =ROUND(J3-K3,2) | M3: 0 | N3: =ROUND(K3-M3,2) | O3: =IF(M3=0,"T0_NoTax",IF(ABS(K3-M3)<0.01,"T1_Clean",IF(L3=0,"T2_FullUnpaid","T3_Mismatch"))) | P3: =I3 | Q3: =IF(LEFT(O3,2)="CM","See Tier Definitions for CM handling",IF(O3="T1_Clean",IF(P3="OK","Edit invoice to remove tax (immediate)","Edit blocked — requires period unlock by accounting"),IF(O3="T2_FullUnpaid","Hold for accounting decision: remove now or wait for payment",IF(O3="T3_Mismatch","Manual investigation of payment trail in NetSuite required",IF(O3="T0_NoTax","Tax not on invoice — flag back to accounting (collection or other issue)",""))))) | R3: Please provide date and check amount if showing paid in your system | Also will need S&U adjusted if it is showing on the invoice.
A4: 90254 | B4: INV668024 | C4: CustInvc | D4: 1727 | E4: Heath Hollis (Burkhart) | F4: 45824 | G4: 45854 | H4: =IFERROR(INDEX('Period Status'!$A$2:$A$16,MATCH(1,(F4>='Period Status'!$C$2:$C$16)*(F4<='Period Status'!$D$2:$D$16),0)),"?") | I4: =IFERROR(VLOOKUP(H4,'Period Status'!$A$2:$I$16,9,FALSE),"?") | J4: 162.36 | K4: 162.36 | L4: =ROUND(J4-K4,2) | M4: 11.65 | N4: =ROUND(K4-M4,2) | O4: =IF(M4=0,"T0_NoTax",IF(ABS(K4-M4)<0.01,"T1_Clean",IF(L4=0,"T2_FullUnpaid","T3_Mismatch"))) | P4: =I4 | Q4: =IF(LEFT(O4,2)="CM","See Tier Definitions for CM handling",IF(O4="T1_Clean",IF(P4="OK","Edit invoice to remove tax (immediate)","Edit blocked — requires period unlock by accounting"),IF(O4="T2_FullUnpaid","Hold for accounting decision: remove now or wait for payment",IF(O4="T3_Mismatch","Manual investigation of payment trail in NetSuite required",IF(O4="T0_NoTax","Tax not on invoice — flag back to accounting (collection or other issue)",""))))) | R4: Please provide date and check amount if showing paid in your system | Also will need S&U adjusted if it is showing on the invoice.
A5: 90329 | B5: INV668030 | C5: CustInvc | D5: 1727 | E5: Heath Hollis (Burkhart) | F5: 45824 | G5: 45854 | H5: =IFERROR(INDEX('Period Status'!$A$2:$A$16,MATCH(1,(F5>='Period Status'!$C$2:$C$16)*(F5<='Period Status'!$D$2:$D$16),0)),"?") | I5: =IFERROR(VLOOKUP(H5,'Period Status'!$A$2:$I$16,9,FALSE),"?") | J5: 185.3 | K5: 185.3 | L5: =ROUND(J5-K5,2) | M5: 17.3 | N5: =ROUND(K5-M5,2) | O5: =IF(M5=0,"T0_NoTax",IF(ABS(K5-M5)<0.01,"T1_Clean",IF(L5=0,"T2_FullUnpaid","T3_Mismatch"))) | P5: =I5 | Q5: =IF(LEFT(O5,2)="CM","See Tier Definitions for CM handling",IF(O5="T1_Clean",IF(P5="OK","Edit invoice to remove tax (immediate)","Edit blocked — requires period unlock by accounting"),IF(O5="T2_FullUnpaid","Hold for accounting decision: remove now or wait for payment",IF(O5="T3_Mismatch","Manual investigation of payment trail in NetSuite required",IF(O5="T0_NoTax","Tax not on invoice — flag back to accounting (collection or other issue)",""))))) | R5: Please provide date and check amount if showing paid in your system | Also will need S&U adjusted if it is showing on the invoice.
A6: 102427 | B6: INV668447 | C6: CustInvc | D6: 314 | E6: Burkhart Dental Supply Company | F6: 45831 | G6: 45861 | H6: =IFERROR(INDEX('Period Status'!$A$2:$A$16,MATCH(1,(F6>='Period Status'!$C$2:$C$16)*(F6<='Period Status'!$D$2:$D$16),0)),"?") | I6: =IFERROR(VLOOKUP(H6,'Period Status'!$A$2:$I$16,9,FALSE),"?") | J6: 235.65 | K6: 235.65 | L6: =ROUND(J6-K6,2) | M6: 0 | N6: =ROUND(K6-M6,2) | O6: =IF(M6=0,"T0_NoTax",IF(ABS(K6-M6)<0.01,"T1_Clean",IF(L6=0,"T2_FullUnpaid","T3_Mismatch"))) | P6: =I6 | Q6: =IF(LEFT(O6,2)="CM","See Tier Definitions for CM handling",IF(O6="T1_Clean",IF(P6="OK","Edit invoice to remove tax (immediate)","Edit blocked — requires period unlock by accounting"),IF(O6="T2_FullUnpaid","Hold for accounting decision: remove now or wait for payment",IF(O6="T3_Mismatch","Manual investigation of payment trail in NetSuite required",IF(O6="T0_NoTax","Tax not on invoice — flag back to accounting (collection or other issue)",""))))) | R6: Please provide date and check amount if showing paid in your system | Also will need S&U adjusted if it is showing on the invoice.
A7: 105194 | B7: CM67526 | C7: CustCred | D7: 314 | E7: Burkhart Dental Supply Company | F7: 45832 | H7: =IFERROR(INDEX('Period Status'!$A$2:$A$16,MATCH(1,(F7>='Period Status'!$C$2:$C$16)*(F7<='Period Status'!$D$2:$D$16),0)),"?") | I7: =IFERROR(VLOOKUP(H7,'Period Status'!$A$2:$I$16,9,FALSE),"?") | J7: -65.5 | K7: -65.5 | L7: N/A (CM) | M7: 0 | N7: N/A (CM) | O7: =IF(ISNUMBER(SEARCH("Recently issued",R7)),"CM_Recent","CM_Pending") | P7: =I7 | Q7: =IF(LEFT(O7,2)="CM","See Tier Definitions for CM handling",IF(O7="T1_Clean",IF(P7="OK","Edit invoice to remove tax (immediate)","Edit blocked — requires period unlock by accounting"),IF(O7="T2_FullUnpaid","Hold for accounting decision: remove now or wait for payment",IF(O7="T3_Mismatch","Manual investigation of payment trail in NetSuite required",IF(O7="T0_NoTax","Tax not on invoice — flag back to accounting (collection or other issue)",""))))) | R7: Please let us know what invoice you would like this applied to
A8: 112423 | B8: INV668779 | C8: CustInvc | D8: 314 | E8: Burkhart Dental Supply Company | F8: 45835 | G8: 45865 | H8: =IFERROR(INDEX('Period Status'!$A$2:$A$16,MATCH(1,(F8>='Period Status'!$C$2:$C$16)*(F8<='Period Status'!$D$2:$D$16),0)),"?") | I8: =IFERROR(VLOOKUP(H8,'Period Status'!$A$2:$I$16,9,FALSE),"?") | J8: 458.8 | K8: 458.8 | L8: =ROUND(J8-K8,2) | M8: 0 | N8: =ROUND(K8-M8,2) | O8: =IF(M8=0,"T0_NoTax",IF(ABS(K8-M8)<0.01,"T1_Clean",IF(L8=0,"T2_FullUnpaid","T3_Mismatch"))) | P8: =I8 | Q8: =IF(LEFT(O8,2)="CM","See Tier Definitions for CM handling",IF(O8="T1_Clean",IF(P8="OK","Edit invoice to remove tax (immediate)","Edit blocked — requires period unlock by accounting"),IF(O8="T2_FullUnpaid","Hold for accounting decision: remove now or wait for payment",IF(O8="T3_Mismatch","Manual investigation of payment trail in NetSuite required",IF(O8="T0_NoTax","Tax not on invoice — flag back to accounting (collection or other issue)",""))))) | R8: Please provide date and check amount if showing paid in your system | Also will need S&U adjusted if it is showing on the invoice.
A9: 112430 | B9: INV668786 | C9: CustInvc | D9: 314 | E9: Burkhart Dental Supply Company | F9: 45835 | G9: 45865 | H9: =IFERROR(INDEX('Period Status'!$A$2:$A$16,MATCH(1,(F9>='Period Status'!$C$2:$C$16)*(F9<='Period Status'!$D$2:$D$16),0)),"?") | I9: =IFERROR(VLOOKUP(H9,'Period Status'!$A$2:$I$16,9,FALSE),"?") | J9: 46.92 | K9: 46.92 | L9: =ROUND(J9-K9,2) | M9: 0 | N9: =ROUND(K9-M9,2) | O9: =IF(M9=0,"T0_NoTax",IF(ABS(K9-M9)<0.01,"T1_Clean",IF(L9=0,"T2_FullUnpaid","T3_Mismatch"))) | P9: =I9 | Q9: =IF(LEFT(O9,2)="CM","See Tier Definitions for CM handling",IF(O9="T1_Clean",IF(P9="OK","Edit invoice to remove tax (immediate)","Edit blocked — requires period unlock by accounting"),IF(O9="T2_FullUnpaid","Hold for accounting decision: remove now or wait for payment",IF(O9="T3_Mismatch","Manual investigation of payment trail in NetSuite required",IF(O9="T0_NoTax","Tax not on invoice — flag back to accounting (collection or other issue)",""))))) | R9: Please provide date and check amount if showing paid in your system | Also will need S&U adjusted if it is showing on the invoice.
A10: 124232 | B10: CM67577 | C10: CustCred | D10: 314 | E10: Burkhart Dental Supply Company | F10: 45841 | H10: =IFERROR(INDEX('Period Status'!$A$2:$A$16,MATCH(1,(F10>='Period Status'!$C$2:$C$16)*(F10<='Period Status'!$D$2:$D$16),0)),"?") | I10: =IFERROR(VLOOKUP(H10,'Period Status'!$A$2:$I$16,9,FALSE),"?") | J10: -27.49 | K10: -27.49 | L10: N/A (CM) | M10: 0 | N10: N/A (CM) | O10: =IF(ISNUMBER(SEARCH("Recently issued",R10)),"CM_Recent","CM_Pending") | P10: =I10 | Q10: =IF(LEFT(O10,2)="CM","See Tier Definitions for CM handling",IF(O10="T1_Clean",IF(P10="OK","Edit invoice to remove tax (immediate)","Edit blocked — requires period unlock by accounting"),IF(O10="T2_FullUnpaid","Hold for accounting decision: remove now or wait for payment",IF(O10="T3_Mismatch","Manual investigation of payment trail in NetSuite required",IF(O10="T0_NoTax","Tax not on invoice — flag back to accounting (collection or other issue)",""))))) | R10: Please let us know what invoice you would like this applied to
A11: 134769 | B11: INV669568 | C11: CustInvc | D11: 1727 | E11: Heath Hollis (Burkhart) | F11: 45847 | G11: 45847 | H11: =IFERROR(INDEX('Period Status'!$A$2:$A$16,MATCH(1,(F11>='Period Status'!$C$2:$C$16)*(F11<='Period Status'!$D$2:$D$16),0)),"?") | I11: =IFERROR(VLOOKUP(H11,'Period Status'!$A$2:$I$16,9,FALSE),"?") | J11: 16.1 | K11: 16.1 | L11: =ROUND(J11-K11,2) | M11: 0 | N11: =ROUND(K11-M11,2) | O11: =IF(M11=0,"T0_NoTax",IF(ABS(K11-M11)<0.01,"T1_Clean",IF(L11=0,"T2_FullUnpaid","T3_Mismatch"))) | P11: =I11 | Q11: =IF(LEFT(O11,2)="CM","See Tier Definitions for CM handling",IF(O11="T1_Clean",IF(P11="OK","Edit invoice to remove tax (immediate)","Edit blocked — requires period unlock by accounting"),IF(O11="T2_FullUnpaid","Hold for accounting decision: remove now or wait for payment",IF(O11="T3_Mismatch","Manual investigation of payment trail in NetSuite required",IF(O11="T0_NoTax","Tax not on invoice — flag back to accounting (collection or other issue)",""))))) | R11: Please provide date and check amount if showing paid in your system | Also will need S&U adjusted if it is showing on the invoice.
A12: 143577 | B12: INV669818 | C12: CustInvc | D12: 314 | E12: Burkhart Dental Supply Company | F12: 45853 | G12: 45883 | H12: =IFERROR(INDEX('Period Status'!$A$2:$A$16,MATCH(1,(F12>='Period Status'!$C$2:$C$16)*(F12<='Period Status'!$D$2:$D$16),0)),"?") | I12: =IFERROR(VLOOKUP(H12,'Period Status'!$A$2:$I$16,9,FALSE),"?") | J12: 468.55 | K12: 468.55 | L12: =ROUND(J12-K12,2) | M12: 0 | N12: =ROUND(K12-M12,2) | O12: =IF(M12=0,"T0_NoTax",IF(ABS(K12-M12)<0.01,"T1_Clean",IF(L12=0,"T2_FullUnpaid","T3_Mismatch"))) | P12: =I12 | Q12: =IF(LEFT(O12,2)="CM","See Tier Definitions for CM handling",IF(O12="T1_Clean",IF(P12="OK","Edit invoice to remove tax (immediate)","Edit blocked — requires period unlock by accounting"),IF(O12="T2_FullUnpaid","Hold for accounting decision: remove now or wait for payment",IF(O12="T3_Mismatch","Manual investigation of payment trail in NetSuite required",IF(O12="T0_NoTax","Tax not on invoice — flag back to accounting (collection or other issue)",""))))) | R12: Please provide date and check amount if showing paid in your system | Also will need S&U adjusted if it is showing on the invoice.
A13: 144382 | B13: INV669855 | C13: CustInvc | D13: 314 | E13: Burkhart Dental Supply Company | F13: 45853 | G13: 45883 | H13: =IFERROR(INDEX('Period Status'!$A$2:$A$16,MATCH(1,(F13>='Period Status'!$C$2:$C$16)*(F13<='Period Status'!$D$2:$D$16),0)),"?") | I13: =IFERROR(VLOOKUP(H13,'Period Status'!$A$2:$I$16,9,FALSE),"?") | J13: 77.85 | K13: 77.85 | L13: =ROUND(J13-K13,2) | M13: 0 | N13: =ROUND(K13-M13,2) | O13: =IF(M13=0,"T0_NoTax",IF(ABS(K13-M13)<0.01,"T1_Clean",IF(L13=0,"T2_FullUnpaid","T3_Mismatch"))) | P13: =I13 | Q13: =IF(LEFT(O13,2)="CM","See Tier Definitions for CM handling",IF(O13="T1_Clean",IF(P13="OK","Edit invoice to remove tax (immediate)","Edit blocked — requires period unlock by accounting"),IF(O13="T2_FullUnpaid","Hold for accounting decision: remove now or wait for payment",IF(O13="T3_Mismatch","Manual investigation of payment trail in NetSuite required",IF(O13="T0_NoTax","Tax not on invoice — flag back to accounting (collection or other issue)",""))))) | R13: Please provide date and check amount if showing paid in your system | Also will need S&U adjusted if it is showing on the invoice.
A14: 146434 | B14: INV669899 | C14: CustInvc | D14: 314 | E14: Burkhart Dental Supply Company | F14: 45854 | G14: 45884 | H14: =IFERROR(INDEX('Period Status'!$A$2:$A$16,MATCH(1,(F14>='Period Status'!$C$2:$C$16)*(F14<='Period Status'!$D$2:$D$16),0)),"?") | I14: =IFERROR(VLOOKUP(H14,'Period Status'!$A$2:$I$16,9,FALSE),"?") | J14: 314.99 | K14: 314.99 | L14: =ROUND(J14-K14,2) | M14: 0 | N14: =ROUND(K14-M14,2) | O14: =IF(M14=0,"T0_NoTax",IF(ABS(K14-M14)<0.01,"T1_Clean",IF(L14=0,"T2_FullUnpaid","T3_Mismatch"))) | P14: =I14 | Q14: =IF(LEFT(O14,2)="CM","See Tier Definitions for CM handling",IF(O14="T1_Clean",IF(P14="OK","Edit invoice to remove tax (immediate)","Edit blocked — requires period unlock by accounting"),IF(O14="T2_FullUnpaid","Hold for accounting decision: remove now or wait for payment",IF(O14="T3_Mismatch","Manual investigation of payment trail in NetSuite required",IF(O14="T0_NoTax","Tax not on invoice — flag back to accounting (collection or other issue)",""))))) | R14: Please provide date and check amount if showing paid in your system | Also will need S&U adjusted if it is showing on the invoice.
A15: 153290 | B15: INV670144 | C15: CustInvc | D15: 314 | E15: Burkhart Dental Supply Company | F15: 45859 | G15: 45889 | H15: =IFERROR(INDEX('Period Status'!$A$2:$A$16,MATCH(1,(F15>='Period Status'!$C$2:$C$16)*(F15<='Period Status'!$D$2:$D$16),0)),"?") | I15: =IFERROR(VLOOKUP(H15,'Period Status'!$A$2:$I$16,9,FALSE),"?") | J15: 77.21 | K15: 77.21 | L15: =ROUND(J15-K15,2) | M15: 0 | N15: =ROUND(K15-M15,2) | O15: =IF(M15=0,"T0_NoTax",IF(ABS(K15-M15)<0.01,"T1_Clean",IF(L15=0,"T2_FullUnpaid","T3_Mismatch"))) | P15: =I15 | Q15: =IF(LEFT(O15,2)="CM","See Tier Definitions for CM handling",IF(O15="T1_Clean",IF(P15="OK","Edit invoice to remove tax (immediate)","Edit blocked — requires period unlock by accounting"),IF(O15="T2_FullUnpaid","Hold for accounting decision: remove now or wait for payment",IF(O15="T3_Mismatch","Manual investigation of payment trail in NetSuite required",IF(O15="T0_NoTax","Tax not on invoice — flag back to accounting (collection or other issue)",""))))) | R15: Please provide date and check amount if showing paid in your system | Also will need S&U adjusted if it is showing on the invoice.
A16: 153306 | B16: INV670160 | C16: CustInvc | D16: 314 | E16: Burkhart Dental Supply Company | F16: 45859 | G16: 45889 | H16: =IFERROR(INDEX('Period Status'!$A$2:$A$16,MATCH(1,(F16>='Period Status'!$C$2:$C$16)*(F16<='Period Status'!$D$2:$D$16),0)),"?") | I16: =IFERROR(VLOOKUP(H16,'Period Status'!$A$2:$I$16,9,FALSE),"?") | J16: 102.93 | K16: 102.93 | L16: =ROUND(J16-K16,2) | M16: 0 | N16: =ROUND(K16-M16,2) | O16: =IF(M16=0,"T0_NoTax",IF(ABS(K16-M16)<0.01,"T1_Clean",IF(L16=0,"T2_FullUnpaid","T3_Mismatch"))) | P16: =I16 | Q16: =IF(LEFT(O16,2)="CM","See Tier Definitions for CM handling",IF(O16="T1_Clean",IF(P16="OK","Edit invoice to remove tax (immediate)","Edit blocked — requires period unlock by accounting"),IF(O16="T2_FullUnpaid","Hold for accounting decision: remove now or wait for payment",IF(O16="T3_Mismatch","Manual investigation of payment trail in NetSuite required",IF(O16="T0_NoTax","Tax not on invoice — flag back to accounting (collection or other issue)",""))))) | R16: Please provide date and check amount if showing paid in your system | Also will need S&U adjusted if it is showing on the invoice.
A17: 158069 | B17: INV670372 | C17: CustInvc | D17: 314 | E17: Burkhart Dental Supply Company | F17: 45861 | G17: 45891 | H17: =IFERROR(INDEX('Period Status'!$A$2:$A$16,MATCH(1,(F17>='Period Status'!$C$2:$C$16)*(F17<='Period Status'!$D$2:$D$16),0)),"?") | I17: =IFERROR(VLOOKUP(H17,'Period Status'!$A$2:$I$16,9,FALSE),"?") | J17: 235.65 | K17: 235.65 | L17: =ROUND(J17-K17,2) | M17: 0 | N17: =ROUND(K17-M17,2) | O17: =IF(M17=0,"T0_NoTax",IF(ABS(K17-M17)<0.01,"T1_Clean",IF(L17=0,"T2_FullUnpaid","T3_Mismatch"))) | P17: =I17 | Q17: =IF(LEFT(O17,2)="CM","See Tier Definitions for CM handling",IF(O17="T1_Clean",IF(P17="OK","Edit invoice to remove tax (immediate)","Edit blocked — requires period unlock by accounting"),IF(O17="T2_FullUnpaid","Hold for accounting decision: remove now or wait for payment",IF(O17="T3_Mismatch","Manual investigation of payment trail in NetSuite required",IF(O17="T0_NoTax","Tax not on invoice — flag back to accounting (collection or other issue)",""))))) | R17: Please provide date and check amount if showing paid in your system | Also will need S&U adjusted if it is showing on the invoice.
A18: 164544 | B18: INV670548 | C18: CustInvc | D18: 314 | E18: Burkhart Dental Supply Company | F18: 45866 | G18: 45896 | H18: =IFERROR(INDEX('Period Status'!$A$2:$A$16,MATCH(1,(F18>='Period Status'!$C$2:$C$16)*(F18<='Period Status'!$D$2:$D$16),0)),"?") | I18: =IFERROR(VLOOKUP(H18,'Period Status'!$A$2:$I$16,9,FALSE),"?") | J18: 120.9 | K18: 120.9 | L18: =ROUND(J18-K18,2) | M18: 0 | N18: =ROUND(K18-M18,2) | O18: =IF(M18=0,"T0_NoTax",IF(ABS(K18-M18)<0.01,"T1_Clean",IF(L18=0,"T2_FullUnpaid","T3_Mismatch"))) | P18: =I18 | Q18: =IF(LEFT(O18,2)="CM","See Tier Definitions for CM handling",IF(O18="T1_Clean",IF(P18="OK","Edit invoice to remove tax (immediate)","Edit blocked — requires period unlock by accounting"),IF(O18="T2_FullUnpaid","Hold for accounting decision: remove now or wait for payment",IF(O18="T3_Mismatch","Manual investigation of payment trail in NetSuite required",IF(O18="T0_NoTax","Tax not on invoice — flag back to accounting (collection or other issue)",""))))) | R18: Please provide date and check amount if showing paid in your system | Also will need S&U adjusted if it is showing on the invoice.
A19: 164590 | B19: INV670590 | C19: CustInvc | D19: 314 | E19: Burkhart Dental Supply Company | F19: 45866 | G19: 45896 | H19: =IFERROR(INDEX('Period Status'!$A$2:$A$16,MATCH(1,(F19>='Period Status'!$C$2:$C$16)*(F19<='Period Status'!$D$2:$D$16),0)),"?") | I19: =IFERROR(VLOOKUP(H19,'Period Status'!$A$2:$I$16,9,FALSE),"?") | J19: 37.26 | K19: 37.26 | L19: =ROUND(J19-K19,2) | M19: 0 | N19: =ROUND(K19-M19,2) | O19: =IF(M19=0,"T0_NoTax",IF(ABS(K19-M19)<0.01,"T1_Clean",IF(L19=0,"T2_FullUnpaid","T3_Mismatch"))) | P19: =I19 | Q19: =IF(LEFT(O19,2)="CM","See Tier Definitions for CM handling",IF(O19="T1_Clean",IF(P19="OK","Edit invoice to remove tax (immediate)","Edit blocked — requires period unlock by accounting"),IF(O19="T2_FullUnpaid","Hold for accounting decision: remove now or wait for payment",IF(O19="T3_Mismatch","Manual investigation of payment trail in NetSuite required",IF(O19="T0_NoTax","Tax not on invoice — flag back to accounting (collection or other issue)",""))))) | R19: Please provide date and check amount if showing paid in your system | Also will need S&U adjusted if it is showing on the invoice.
A20: 171660 | B20: CM67624 | C20: CustCred | D20: 1727 | E20: Heath Hollis (Burkhart) | F20: 45869 | H20: =IFERROR(INDEX('Period Status'!$A$2:$A$16,MATCH(1,(F20>='Period Status'!$C$2:$C$16)*(F20<='Period Status'!$D$2:$D$16),0)),"?") | I20: =IFERROR(VLOOKUP(H20,'Period Status'!$A$2:$I$16,9,FALSE),"?") | J20: -16.1 | K20: -16.1 | L20: N/A (CM) | M20: 0 | N20: N/A (CM) | O20: =IF(ISNUMBER(SEARCH("Recently issued",R20)),"CM_Recent","CM_Pending") | P20: =I20 | Q20: =IF(LEFT(O20,2)="CM","See Tier Definitions for CM handling",IF(O20="T1_Clean",IF(P20="OK","Edit invoice to remove tax (immediate)","Edit blocked — requires period unlock by accounting"),IF(O20="T2_FullUnpaid","Hold for accounting decision: remove now or wait for payment",IF(O20="T3_Mismatch","Manual investigation of payment trail in NetSuite required",IF(O20="T0_NoTax","Tax not on invoice — flag back to accounting (collection or other issue)",""))))) | R20: Please let us know what invoice you would like this applied to
A21: 190737 | B21: INV671502 | C21: CustInvc | D21: 1727 | E21: Heath Hollis (Burkhart) | F21: 45877 | G21: 45877 | H21: =IFERROR(INDEX('Period Status'!$A$2:$A$16,MATCH(1,(F21>='Period Status'!$C$2:$C$16)*(F21<='Period Status'!$D$2:$D$16),0)),"?") | I21: =IFERROR(VLOOKUP(H21,'Period Status'!$A$2:$I$16,9,FALSE),"?") | J21: 43.62 | K21: 1.13 | L21: =ROUND(J21-K21,2) | M21: 1.13 | N21: =ROUND(K21-M21,2) | O21: =IF(M21=0,"T0_NoTax",IF(ABS(K21-M21)<0.01,"T1_Clean",IF(L21=0,"T2_FullUnpaid","T3_Mismatch"))) | P21: =I21 | Q21: =IF(LEFT(O21,2)="CM","See Tier Definitions for CM handling",IF(O21="T1_Clean",IF(P21="OK","Edit invoice to remove tax (immediate)","Edit blocked — requires period unlock by accounting"),IF(O21="T2_FullUnpaid","Hold for accounting decision: remove now or wait for payment",IF(O21="T3_Mismatch","Manual investigation of payment trail in NetSuite required",IF(O21="T0_NoTax","Tax not on invoice — flag back to accounting (collection or other issue)",""))))) | R21: Sales Tax - Received exemption certificate, will resolve shortly
A22: 265488 | B22: INV674001 | C22: CustInvc | D22: 314 | E22: Burkhart Dental Supply Company | F22: 45919 | G22: 45949 | H22: =IFERROR(INDEX('Period Status'!$A$2:$A$16,MATCH(1,(F22>='Period Status'!$C$2:$C$16)*(F22<='Period Status'!$D$2:$D$16),0)),"?") | I22: =IFERROR(VLOOKUP(H22,'Period Status'!$A$2:$I$16,9,FALSE),"?") | J22: 233.37 | K22: 233.37 | L22: =ROUND(J22-K22,2) | M22: 0 | N22: =ROUND(K22-M22,2) | O22: =IF(M22=0,"T0_NoTax",IF(ABS(K22-M22)<0.01,"T1_Clean",IF(L22=0,"T2_FullUnpaid","T3_Mismatch"))) | P22: =I22 | Q22: =IF(LEFT(O22,2)="CM","See Tier Definitions for CM handling",IF(O22="T1_Clean",IF(P22="OK","Edit invoice to remove tax (immediate)","Edit blocked — requires period unlock by accounting"),IF(O22="T2_FullUnpaid","Hold for accounting decision: remove now or wait for payment",IF(O22="T3_Mismatch","Manual investigation of payment trail in NetSuite required",IF(O22="T0_NoTax","Tax not on invoice — flag back to accounting (collection or other issue)",""))))) | R22: Please provide date and check amount if showing paid in your system | Also will need S&U adjusted if it is showing on the invoice.
A23: 265492 | B23: INV674004 | C23: CustInvc | D23: 314 | E23: Burkhart Dental Supply Company | F23: 45919 | G23: 45949 | H23: =IFERROR(INDEX('Period Status'!$A$2:$A$16,MATCH(1,(F23>='Period Status'!$C$2:$C$16)*(F23<='Period Status'!$D$2:$D$16),0)),"?") | I23: =IFERROR(VLOOKUP(H23,'Period Status'!$A$2:$I$16,9,FALSE),"?") | J23: 37.8 | K23: 37.8 | L23: =ROUND(J23-K23,2) | M23: 0 | N23: =ROUND(K23-M23,2) | O23: =IF(M23=0,"T0_NoTax",IF(ABS(K23-M23)<0.01,"T1_Clean",IF(L23=0,"T2_FullUnpaid","T3_Mismatch"))) | P23: =I23 | Q23: =IF(LEFT(O23,2)="CM","See Tier Definitions for CM handling",IF(O23="T1_Clean",IF(P23="OK","Edit invoice to remove tax (immediate)","Edit blocked — requires period unlock by accounting"),IF(O23="T2_FullUnpaid","Hold for accounting decision: remove now or wait for payment",IF(O23="T3_Mismatch","Manual investigation of payment trail in NetSuite required",IF(O23="T0_NoTax","Tax not on invoice — flag back to accounting (collection or other issue)",""))))) | R23: Please provide date and check amount if showing paid in your system | Also will need S&U adjusted if it is showing on the invoice.
A24: 266351 | B24: CM67656 | C24: CustCred | D24: 1727 | E24: Heath Hollis (Burkhart) | F24: 45922 | H24: =IFERROR(INDEX('Period Status'!$A$2:$A$16,MATCH(1,(F24>='Period Status'!$C$2:$C$16)*(F24<='Period Status'!$D$2:$D$16),0)),"?") | I24: =IFERROR(VLOOKUP(H24,'Period Status'!$A$2:$I$16,9,FALSE),"?") | J24: -16.1 | K24: -16.1 | L24: N/A (CM) | M24: 0 | N24: N/A (CM) | O24: =IF(ISNUMBER(SEARCH("Recently issued",R24)),"CM_Recent","CM_Pending") | P24: =I24 | Q24: =IF(LEFT(O24,2)="CM","See Tier Definitions for CM handling",IF(O24="T1_Clean",IF(P24="OK","Edit invoice to remove tax (immediate)","Edit blocked — requires period unlock by accounting"),IF(O24="T2_FullUnpaid","Hold for accounting decision: remove now or wait for payment",IF(O24="T3_Mismatch","Manual investigation of payment trail in NetSuite required",IF(O24="T0_NoTax","Tax not on invoice — flag back to accounting (collection or other issue)",""))))) | R24: Please let us know what invoice you would like this applied to
A25: 269416 | B25: INV674152 | C25: CustInvc | D25: 1727 | E25: Heath Hollis (Burkhart) | F25: 45923 | G25: 45953 | H25: =IFERROR(INDEX('Period Status'!$A$2:$A$16,MATCH(1,(F25>='Period Status'!$C$2:$C$16)*(F25<='Period Status'!$D$2:$D$16),0)),"?") | I25: =IFERROR(VLOOKUP(H25,'Period Status'!$A$2:$I$16,9,FALSE),"?") | J25: 37.97 | K25: 37.97 | L25: =ROUND(J25-K25,2) | M25: 1.23 | N25: =ROUND(K25-M25,2) | O25: =IF(M25=0,"T0_NoTax",IF(ABS(K25-M25)<0.01,"T1_Clean",IF(L25=0,"T2_FullUnpaid","T3_Mismatch"))) | P25: =I25 | Q25: =IF(LEFT(O25,2)="CM","See Tier Definitions for CM handling",IF(O25="T1_Clean",IF(P25="OK","Edit invoice to remove tax (immediate)","Edit blocked — requires period unlock by accounting"),IF(O25="T2_FullUnpaid","Hold for accounting decision: remove now or wait for payment",IF(O25="T3_Mismatch","Manual investigation of payment trail in NetSuite required",IF(O25="T0_NoTax","Tax not on invoice — flag back to accounting (collection or other issue)",""))))) | R25: Please provide date and check amount if showing paid in your system | Also will need S&U adjusted if it is showing on the invoice.
A26: 273777 | B26: INV674349 | C26: CustInvc | D26: 314 | E26: Burkhart Dental Supply Company | F26: 45925 | G26: 45955 | H26: =IFERROR(INDEX('Period Status'!$A$2:$A$16,MATCH(1,(F26>='Period Status'!$C$2:$C$16)*(F26<='Period Status'!$D$2:$D$16),0)),"?") | I26: =IFERROR(VLOOKUP(H26,'Period Status'!$A$2:$I$16,9,FALSE),"?") | J26: 29.59 | K26: 29.59 | L26: =ROUND(J26-K26,2) | M26: 0 | N26: =ROUND(K26-M26,2) | O26: =IF(M26=0,"T0_NoTax",IF(ABS(K26-M26)<0.01,"T1_Clean",IF(L26=0,"T2_FullUnpaid","T3_Mismatch"))) | P26: =I26 | Q26: =IF(LEFT(O26,2)="CM","See Tier Definitions for CM handling",IF(O26="T1_Clean",IF(P26="OK","Edit invoice to remove tax (immediate)","Edit blocked — requires period unlock by accounting"),IF(O26="T2_FullUnpaid","Hold for accounting decision: remove now or wait for payment",IF(O26="T3_Mismatch","Manual investigation of payment trail in NetSuite required",IF(O26="T0_NoTax","Tax not on invoice — flag back to accounting (collection or other issue)",""))))) | R26: Please provide date and check amount if showing paid in your system | Also will need S&U adjusted if it is showing on the invoice.
A27: 288039 | B27: INV675167 | C27: CustInvc | D27: 314 | E27: Burkhart Dental Supply Company | F27: 45933 | G27: 45963 | H27: =IFERROR(INDEX('Period Status'!$A$2:$A$16,MATCH(1,(F27>='Period Status'!$C$2:$C$16)*(F27<='Period Status'!$D$2:$D$16),0)),"?") | I27: =IFERROR(VLOOKUP(H27,'Period Status'!$A$2:$I$16,9,FALSE),"?") | J27: 122.99 | K27: 122.99 | L27: =ROUND(J27-K27,2) | M27: 0 | N27: =ROUND(K27-M27,2) | O27: =IF(M27=0,"T0_NoTax",IF(ABS(K27-M27)<0.01,"T1_Clean",IF(L27=0,"T2_FullUnpaid","T3_Mismatch"))) | P27: =I27 | Q27: =IF(LEFT(O27,2)="CM","See Tier Definitions for CM handling",IF(O27="T1_Clean",IF(P27="OK","Edit invoice to remove tax (immediate)","Edit blocked — requires period unlock by accounting"),IF(O27="T2_FullUnpaid","Hold for accounting decision: remove now or wait for payment",IF(O27="T3_Mismatch","Manual investigation of payment trail in NetSuite required",IF(O27="T0_NoTax","Tax not on invoice — flag back to accounting (collection or other issue)",""))))) | R27: Please provide date and check amount if showing paid in your system | Also will need S&U adjusted if it is showing on the invoice.
A28: 288042 | B28: INV675170 | C28: CustInvc | D28: 1727 | E28: Heath Hollis (Burkhart) | F28: 45933 | G28: 45963 | H28: =IFERROR(INDEX('Period Status'!$A$2:$A$16,MATCH(1,(F28>='Period Status'!$C$2:$C$16)*(F28<='Period Status'!$D$2:$D$16),0)),"?") | I28: =IFERROR(VLOOKUP(H28,'Period Status'!$A$2:$I$16,9,FALSE),"?") | J28: 393.28 | K28: 393.28 | L28: =ROUND(J28-K28,2) | M28: 8.99 | N28: =ROUND(K28-M28,2) | O28: =IF(M28=0,"T0_NoTax",IF(ABS(K28-M28)<0.01,"T1_Clean",IF(L28=0,"T2_FullUnpaid","T3_Mismatch"))) | P28: =I28 | Q28: =IF(LEFT(O28,2)="CM","See Tier Definitions for CM handling",IF(O28="T1_Clean",IF(P28="OK","Edit invoice to remove tax (immediate)","Edit blocked — requires period unlock by accounting"),IF(O28="T2_FullUnpaid","Hold for accounting decision: remove now or wait for payment",IF(O28="T3_Mismatch","Manual investigation of payment trail in NetSuite required",IF(O28="T0_NoTax","Tax not on invoice — flag back to accounting (collection or other issue)",""))))) | R28: Please provide date and check amount if showing paid in your system | Also will need S&U adjusted if it is showing on the invoice.
A29: 295090 | B29: INV675518 | C29: CustInvc | D29: 314 | E29: Burkhart Dental Supply Company | F29: 45939 | G29: 45969 | H29: =IFERROR(INDEX('Period Status'!$A$2:$A$16,MATCH(1,(F29>='Period Status'!$C$2:$C$16)*(F29<='Period Status'!$D$2:$D$16),0)),"?") | I29: =IFERROR(VLOOKUP(H29,'Period Status'!$A$2:$I$16,9,FALSE),"?") | J29: 69.88 | K29: 69.88 | L29: =ROUND(J29-K29,2) | M29: 0 | N29: =ROUND(K29-M29,2) | O29: =IF(M29=0,"T0_NoTax",IF(ABS(K29-M29)<0.01,"T1_Clean",IF(L29=0,"T2_FullUnpaid","T3_Mismatch"))) | P29: =I29 | Q29: =IF(LEFT(O29,2)="CM","See Tier Definitions for CM handling",IF(O29="T1_Clean",IF(P29="OK","Edit invoice to remove tax (immediate)","Edit blocked — requires period unlock by accounting"),IF(O29="T2_FullUnpaid","Hold for accounting decision: remove now or wait for payment",IF(O29="T3_Mismatch","Manual investigation of payment trail in NetSuite required",IF(O29="T0_NoTax","Tax not on invoice — flag back to accounting (collection or other issue)",""))))) | R29: Please provide date and check amount if showing paid in your system | Also will need S&U adjusted if it is showing on the invoice.
A30: 295111 | B30: INV675538 | C30: CustInvc | D30: 314 | E30: Burkhart Dental Supply Company | F30: 45939 | G30: 45969 | H30: =IFERROR(INDEX('Period Status'!$A$2:$A$16,MATCH(1,(F30>='Period Status'!$C$2:$C$16)*(F30<='Period Status'!$D$2:$D$16),0)),"?") | I30: =IFERROR(VLOOKUP(H30,'Period Status'!$A$2:$I$16,9,FALSE),"?") | J30: 447.75 | K30: 447.75 | L30: =ROUND(J30-K30,2) | M30: 0 | N30: =ROUND(K30-M30,2) | O30: =IF(M30=0,"T0_NoTax",IF(ABS(K30-M30)<0.01,"T1_Clean",IF(L30=0,"T2_FullUnpaid","T3_Mismatch"))) | P30: =I30 | Q30: =IF(LEFT(O30,2)="CM","See Tier Definitions for CM handling",IF(O30="T1_Clean",IF(P30="OK","Edit invoice to remove tax (immediate)","Edit blocked — requires period unlock by accounting"),IF(O30="T2_FullUnpaid","Hold for accounting decision: remove now or wait for payment",IF(O30="T3_Mismatch","Manual investigation of payment trail in NetSuite required",IF(O30="T0_NoTax","Tax not on invoice — flag back to accounting (collection or other issue)",""))))) | R30: Please provide date and check amount if showing paid in your system | Also will need S&U adjusted if it is showing on the invoice.
A31: 295120 | B31: INV675546 | C31: CustInvc | D31: 314 | E31: Burkhart Dental Supply Company | F31: 45939 | G31: 45969 | H31: =IFERROR(INDEX('Period Status'!$A$2:$A$16,MATCH(1,(F31>='Period Status'!$C$2:$C$16)*(F31<='Period Status'!$D$2:$D$16),0)),"?") | I31: =IFERROR(VLOOKUP(H31,'Period Status'!$A$2:$I$16,9,FALSE),"?") | J31: 31.28 | K31: 31.28 | L31: =ROUND(J31-K31,2) | M31: 0 | N31: =ROUND(K31-M31,2) | O31: =IF(M31=0,"T0_NoTax",IF(ABS(K31-M31)<0.01,"T1_Clean",IF(L31=0,"T2_FullUnpaid","T3_Mismatch"))) | P31: =I31 | Q31: =IF(LEFT(O31,2)="CM","See Tier Definitions for CM handling",IF(O31="T1_Clean",IF(P31="OK","Edit invoice to remove tax (immediate)","Edit blocked — requires period unlock by accounting"),IF(O31="T2_FullUnpaid","Hold for accounting decision: remove now or wait for payment",IF(O31="T3_Mismatch","Manual investigation of payment trail in NetSuite required",IF(O31="T0_NoTax","Tax not on invoice — flag back to accounting (collection or other issue)",""))))) | R31: Please provide date and check amount if showing paid in your system | Also will need S&U adjusted if it is showing on the invoice.
A32: 337114 | B32: INV676813 | C32: CustInvc | D32: 1727 | E32: Heath Hollis (Burkhart) | F32: 45964 | G32: 45994 | H32: =IFERROR(INDEX('Period Status'!$A$2:$A$16,MATCH(1,(F32>='Period Status'!$C$2:$C$16)*(F32<='Period Status'!$D$2:$D$16),0)),"?") | I32: =IFERROR(VLOOKUP(H32,'Period Status'!$A$2:$I$16,9,FALSE),"?") | J32: 87.31 | K32: 8.16 | L32: =ROUND(J32-K32,2) | M32: 8.16 | N32: =ROUND(K32-M32,2) | O32: =IF(M32=0,"T0_NoTax",IF(ABS(K32-M32)<0.01,"T1_Clean",IF(L32=0,"T2_FullUnpaid","T3_Mismatch"))) | P32: =I32 | Q32: =IF(LEFT(O32,2)="CM","See Tier Definitions for CM handling",IF(O32="T1_Clean",IF(P32="OK","Edit invoice to remove tax (immediate)","Edit blocked — requires period unlock by accounting"),IF(O32="T2_FullUnpaid","Hold for accounting decision: remove now or wait for payment",IF(O32="T3_Mismatch","Manual investigation of payment trail in NetSuite required",IF(O32="T0_NoTax","Tax not on invoice — flag back to accounting (collection or other issue)",""))))) | R32: Sales Tax - Received exemption certificate, will resolve shortly
A33: 354456 | B33: INV677300 | C33: CustInvc | D33: 1727 | E33: Heath Hollis (Burkhart) | F33: 45968 | G33: 45998 | H33: =IFERROR(INDEX('Period Status'!$A$2:$A$16,MATCH(1,(F33>='Period Status'!$C$2:$C$16)*(F33<='Period Status'!$D$2:$D$16),0)),"?") | I33: =IFERROR(VLOOKUP(H33,'Period Status'!$A$2:$I$16,9,FALSE),"?") | J33: 209.92 | K33: 12.53 | L33: =ROUND(J33-K33,2) | M33: 12.53 | N33: =ROUND(K33-M33,2) | O33: =IF(M33=0,"T0_NoTax",IF(ABS(K33-M33)<0.01,"T1_Clean",IF(L33=0,"T2_FullUnpaid","T3_Mismatch"))) | P33: =I33 | Q33: =IF(LEFT(O33,2)="CM","See Tier Definitions for CM handling",IF(O33="T1_Clean",IF(P33="OK","Edit invoice to remove tax (immediate)","Edit blocked — requires period unlock by accounting"),IF(O33="T2_FullUnpaid","Hold for accounting decision: remove now or wait for payment",IF(O33="T3_Mismatch","Manual investigation of payment trail in NetSuite required",IF(O33="T0_NoTax","Tax not on invoice — flag back to accounting (collection or other issue)",""))))) | R33: Sales Tax - Received exemption certificate, will resolve shortly
A34: 354462 | B34: INV677305 | C34: CustInvc | D34: 1727 | E34: Heath Hollis (Burkhart) | F34: 45968 | G34: 45998 | H34: =IFERROR(INDEX('Period Status'!$A$2:$A$16,MATCH(1,(F34>='Period Status'!$C$2:$C$16)*(F34<='Period Status'!$D$2:$D$16),0)),"?") | I34: =IFERROR(VLOOKUP(H34,'Period Status'!$A$2:$I$16,9,FALSE),"?") | J34: 52.69 | K34: 2.91 | L34: =ROUND(J34-K34,2) | M34: 2.91 | N34: =ROUND(K34-M34,2) | O34: =IF(M34=0,"T0_NoTax",IF(ABS(K34-M34)<0.01,"T1_Clean",IF(L34=0,"T2_FullUnpaid","T3_Mismatch"))) | P34: =I34 | Q34: =IF(LEFT(O34,2)="CM","See Tier Definitions for CM handling",IF(O34="T1_Clean",IF(P34="OK","Edit invoice to remove tax (immediate)","Edit blocked — requires period unlock by accounting"),IF(O34="T2_FullUnpaid","Hold for accounting decision: remove now or wait for payment",IF(O34="T3_Mismatch","Manual investigation of payment trail in NetSuite required",IF(O34="T0_NoTax","Tax not on invoice — flag back to accounting (collection or other issue)",""))))) | R34: Sales Tax - Received exemption certificate, will resolve shortly
A35: 370607 | B35: INV677626 | C35: CustInvc | D35: 1727 | E35: Heath Hollis (Burkhart) | F35: 45975 | G35: 46005 | H35: =IFERROR(INDEX('Period Status'!$A$2:$A$16,MATCH(1,(F35>='Period Status'!$C$2:$C$16)*(F35<='Period Status'!$D$2:$D$16),0)),"?") | I35: =IFERROR(VLOOKUP(H35,'Period Status'!$A$2:$I$16,9,FALSE),"?") | J35: 67.35 | K35: 5.14 | L35: =ROUND(J35-K35,2) | M35: 5.14 | N35: =ROUND(K35-M35,2) | O35: =IF(M35=0,"T0_NoTax",IF(ABS(K35-M35)<0.01,"T1_Clean",IF(L35=0,"T2_FullUnpaid","T3_Mismatch"))) | P35: =I35 | Q35: =IF(LEFT(O35,2)="CM","See Tier Definitions for CM handling",IF(O35="T1_Clean",IF(P35="OK","Edit invoice to remove tax (immediate)","Edit blocked — requires period unlock by accounting"),IF(O35="T2_FullUnpaid","Hold for accounting decision: remove now or wait for payment",IF(O35="T3_Mismatch","Manual investigation of payment trail in NetSuite required",IF(O35="T0_NoTax","Tax not on invoice — flag back to accounting (collection or other issue)",""))))) | R35: Sales Tax - Received exemption certificate, will resolve shortly
A36: 385492 | B36: INV678085 | C36: CustInvc | D36: 1727 | E36: Heath Hollis (Burkhart) | F36: 45982 | G36: 46012 | H36: =IFERROR(INDEX('Period Status'!$A$2:$A$16,MATCH(1,(F36>='Period Status'!$C$2:$C$16)*(F36<='Period Status'!$D$2:$D$16),0)),"?") | I36: =IFERROR(VLOOKUP(H36,'Period Status'!$A$2:$I$16,9,FALSE),"?") | J36: 80.44 | K36: 1.58 | L36: =ROUND(J36-K36,2) | M36: 1.58 | N36: =ROUND(K36-M36,2) | O36: =IF(M36=0,"T0_NoTax",IF(ABS(K36-M36)<0.01,"T1_Clean",IF(L36=0,"T2_FullUnpaid","T3_Mismatch"))) | P36: =I36 | Q36: =IF(LEFT(O36,2)="CM","See Tier Definitions for CM handling",IF(O36="T1_Clean",IF(P36="OK","Edit invoice to remove tax (immediate)","Edit blocked — requires period unlock by accounting"),IF(O36="T2_FullUnpaid","Hold for accounting decision: remove now or wait for payment",IF(O36="T3_Mismatch","Manual investigation of payment trail in NetSuite required",IF(O36="T0_NoTax","Tax not on invoice — flag back to accounting (collection or other issue)",""))))) | R36: Sales Tax - Received exemption certificate, will resolve shortly
... A107: 830842 | B107: INV690202 | C107: CustInvc | D107: 1727 | E107: Heath Hollis (Burkhart) | F107: 46185 | G107: 46215 | H107: =IFERROR(INDEX('Period Status'!$A$2:$A$16,MATCH(1,(F107>='Period Status'!$C$2:$C$16)*(F107<='Period Status'!$D$2:$D$16),0)),"?") | I107: =IFERROR(VLOOKUP(H107,'Period Status'!$A$2:$I$16,9,FALSE),"?") | J107: 281.09 | K107: 281.09 | L107: =ROUND(J107-K107,2) | M107: 22.53 | N107: =ROUND(K107-M107,2) | O107: =IF(M107=0,"T0_NoTax",IF(ABS(K107-M107)<0.01,"T1_Clean",IF(L107=0,"T2_FullUnpaid","T3_Mismatch"))) | P107: =I107 | Q107: =IF(LEFT(O107,2)="CM","See Tier Definitions for CM handling",IF(O107="T1_Clean",IF(P107="OK","Edit invoice to remove tax (immediate)","Edit blocked — requires period unlock by accounting"),IF(O107="T2_FullUnpaid","Hold for accounting decision: remove now or wait for payment",IF(O107="T3_Mismatch","Manual investigation of payment trail in NetSuite required",IF(O107="T0_NoTax","Tax not on invoice — flag back to accounting (collection or other issue)",""))))) | R107: Current | Also will need S&U adjusted if it is showing on the invoice.
A108: 835108 | B108: CM67942 | C108: CustCred | D108: 1727 | E108: Heath Hollis (Burkhart) | F108: 46188 | H108: =IFERROR(INDEX('Period Status'!$A$2:$A$16,MATCH(1,(F108>='Period Status'!$C$2:$C$16)*(F108<='Period Status'!$D$2:$D$16),0)),"?") | I108: =IFERROR(VLOOKUP(H108,'Period Status'!$A$2:$I$16,9,FALSE),"?") | J108: -44.32 | K108: -44.32 | L108: N/A (CM) | M108: 0 | N108: N/A (CM) | O108: =IF(ISNUMBER(SEARCH("Recently issued",R108)),"CM_Recent","CM_Pending") | P108: =I108 | Q108: =IF(LEFT(O108,2)="CM","See Tier Definitions for CM handling",IF(O108="T1_Clean",IF(P108="OK","Edit invoice to remove tax (immediate)","Edit blocked — requires period unlock by accounting"),IF(O108="T2_FullUnpaid","Hold for accounting decision: remove now or wait for payment",IF(O108="T3_Mismatch","Manual investigation of payment trail in NetSuite required",IF(O108="T0_NoTax","Tax not on invoice — flag back to accounting (collection or other issue)",""))))) | R108: Recently issued, copies are included in email
A109: 835121 | B109: CM67955 | C109: CustCred | D109: 1727 | E109: Heath Hollis (Burkhart) | F109: 46188 | H109: =IFERROR(INDEX('Period Status'!$A$2:$A$16,MATCH(1,(F109>='Period Status'!$C$2:$C$16)*(F109<='Period Status'!$D$2:$D$16),0)),"?") | I109: =IFERROR(VLOOKUP(H109,'Period Status'!$A$2:$I$16,9,FALSE),"?") | J109: -58.28 | K109: -58.28 | L109: N/A (CM) | M109: 0 | N109: N/A (CM) | O109: =IF(ISNUMBER(SEARCH("Recently issued",R109)),"CM_Recent","CM_Pending") | P109: =I109 | Q109: =IF(LEFT(O109,2)="CM","See Tier Definitions for CM handling",IF(O109="T1_Clean",IF(P109="OK","Edit invoice to remove tax (immediate)","Edit blocked — requires period unlock by accounting"),IF(O109="T2_FullUnpaid","Hold for accounting decision: remove now or wait for payment",IF(O109="T3_Mismatch","Manual investigation of payment trail in NetSuite required",IF(O109="T0_NoTax","Tax not on invoice — flag back to accounting (collection or other issue)",""))))) | R109: Recently issued, copies are included in email
A110: 837682 | B110: INV690376 | C110: CustInvc | D110: 1727 | E110: Heath Hollis (Burkhart) | F110: 46189 | G110: 46219 | H110: =IFERROR(INDEX('Period Status'!$A$2:$A$16,MATCH(1,(F110>='Period Status'!$C$2:$C$16)*(F110<='Period Status'!$D$2:$D$16),0)),"?") | I110: =IFERROR(VLOOKUP(H110,'Period Status'!$A$2:$I$16,9,FALSE),"?") | J110: 75.02 | K110: 75.02 | L110: =ROUND(J110-K110,2) | M110: 0 | N110: =ROUND(K110-M110,2) | O110: =IF(M110=0,"T0_NoTax",IF(ABS(K110-M110)<0.01,"T1_Clean",IF(L110=0,"T2_FullUnpaid","T3_Mismatch"))) | P110: =I110 | Q110: =IF(LEFT(O110,2)="CM","See Tier Definitions for CM handling",IF(O110="T1_Clean",IF(P110="OK","Edit invoice to remove tax (immediate)","Edit blocked — requires period unlock by accounting"),IF(O110="T2_FullUnpaid","Hold for accounting decision: remove now or wait for payment",IF(O110="T3_Mismatch","Manual investigation of payment trail in NetSuite required",IF(O110="T0_NoTax","Tax not on invoice — flag back to accounting (collection or other issue)",""))))) | R110: Current | Also will need S&U adjusted if it is showing on the invoice.
...

Sheet Period Status
A1: Period Name | B1: NS Internal ID | C1: Start Date | D1: End Date | E1: Closed (T/F) | F1: All Locked (T/F) | G1: AR Locked (T/F) | H1: Allow Non-GL (T/F) | I1: Feasibility
A2: Jun 2025 | B2: 26 | C2: 45809 | D2: 45838 | E2: T | F2: T | G2: T | H2: F | I2: =IF(AND(E2="F",G2="F"),"OK",IF(AND(E2="F",G2="T"),"AR LOCKED","CLOSED+LOCKED"))
A3: Jul 2025 | B3: 28 | C3: 45839 | D3: 45869 | E3: T | F3: T | G3: T | H3: F | I3: =IF(AND(E3="F",G3="F"),"OK",IF(AND(E3="F",G3="T"),"AR LOCKED","CLOSED+LOCKED"))
A4: Aug 2025 | B4: 29 | C4: 45870 | D4: 45900 | E4: T | F4: T | G4: T | H4: F | I4: =IF(AND(E4="F",G4="F"),"OK",IF(AND(E4="F",G4="T"),"AR LOCKED","CLOSED+LOCKED"))
A5: Sep 2025 | B5: 30 | C5: 45901 | D5: 45930 | E5: T | F5: T | G5: T | H5: F | I5: =IF(AND(E5="F",G5="F"),"OK",IF(AND(E5="F",G5="T"),"AR LOCKED","CLOSED+LOCKED"))
A6: Oct 2025 | B6: 32 | C6: 45931 | D6: 45961 | E6: T | F6: T | G6: T | H6: F | I6: =IF(AND(E6="F",G6="F"),"OK",IF(AND(E6="F",G6="T"),"AR LOCKED","CLOSED+LOCKED"))
A7: Nov 2025 | B7: 33 | C7: 45962 | D7: 45991 | E7: T | F7: T | G7: T | H7: F | I7: =IF(AND(E7="F",G7="F"),"OK",IF(AND(E7="F",G7="T"),"AR LOCKED","CLOSED+LOCKED"))
A8: Dec 2025 | B8: 34 | C8: 45992 | D8: 46022 | E8: T | F8: T | G8: T | H8: F | I8: =IF(AND(E8="F",G8="F"),"OK",IF(AND(E8="F",G8="T"),"AR LOCKED","CLOSED+LOCKED"))
A9: Jan 2026 | B9: 37 | C9: 46023 | D9: 46053 | E9: T | F9: T | G9: T | H9: T | I9: =IF(AND(E9="F",G9="F"),"OK",IF(AND(E9="F",G9="T"),"AR LOCKED","CLOSED+LOCKED"))
A10: Feb 2026 | B10: 38 | C10: 46054 | D10: 46081 | E10: T | F10: T | G10: T | H10: T | I10: =IF(AND(E10="F",G10="F"),"OK",IF(AND(E10="F",G10="T"),"AR LOCKED","CLOSED+LOCKED"))
A11: Mar 2026 | B11: 39 | C11: 46082 | D11: 46112 | E11: T | F11: T | G11: T | H11: F | I11: =IF(AND(E11="F",G11="F"),"OK",IF(AND(E11="F",G11="T"),"AR LOCKED","CLOSED+LOCKED"))
A12: Apr 2026 | B12: 41 | C12: 46113 | D12: 46142 | E12: F | F12: T | G12: T | H12: T | I12: =IF(AND(E12="F",G12="F"),"OK",IF(AND(E12="F",G12="T"),"AR LOCKED","CLOSED+LOCKED"))
A13: May 2026 | B13: 42 | C13: 46143 | D13: 46173 | E13: F | F13: F | G13: F | H13: F | I13: =IF(AND(E13="F",G13="F"),"OK",IF(AND(E13="F",G13="T"),"AR LOCKED","CLOSED+LOCKED"))
... A16: Apr 2025 | B16: 24 | C16: 45748 | D16: 45777 | E16: T | F16: T | G16: T | H16: F | I16: =IF(AND(E16="F",G16="F"),"OK",IF(AND(E16="F",G16="T"),"AR LOCKED","CLOSED+LOCKED"))

Sheet Tier Definitions
A1: Tier | B1: Source Note (from accounting) | C1: Condition (vs NetSuite data) | D1: Tax Removal Applicable? | E1: Recommended Action
A2: T1_Clean | B2: Sales Tax - Received exemption certificate, will resolve shortly | C2: Tax > 0 AND Unpaid == Tax (±$0.01) | D2: YES — directly applicable | E2: Edit invoice to remove tax → balance becomes $0
A3: T2_FullUnpaid | B3: Multiple (current / within 30 / exemption cert) | C3: Tax > 0 AND Paid = $0 AND Unpaid = Original | D3: PENDING — awaiting payment decision | E3: Hold for accounting decision: remove now (since exempt) or wait for payment
A4: T3_Mismatch | B4: Multiple | C4: Tax > 0 AND Paid > 0 AND Unpaid ≠ Tax | D4: INVESTIGATE — manual review needed | E4: Investigate payment application in NetSuite before any change
A5: T0_NoTax | B5: Various | C5: Tax = 0 on invoice | D5: NO — nothing to remove | E5: Flag back to accounting — different issue (likely collection)
A6: CM_Pending | B6: Please let us know what invoice you would like this applied to | C6: Type = CustCred, no application | D6: N/A — credit memo | E6: Get application instruction from accounting
A7: CM_Recent | B7: Recently issued, copies are included in email | C7: Type = CustCred, recently issued | D7: N/A — credit memo | E7: Informational; apply per accounting
